<?xml version="1.0" ?>
<!-- =================================================================================== -->
<!-- |    This document was autogenerated by xacro from piper_l_description.xacro      | -->
<!-- |    EDITING THIS FILE BY HAND IS NOT RECOMMENDED                                 | -->
<!-- =================================================================================== -->
<!-- This URDF was automatically created by SolidWorks to URDF Exporter! Originally created by Stephen Brawner (brawner@gmail.com) 
     Commit Version: 1.6.0-4-g7f85cfe  Build Version: 1.6.7995.38578
     For more information, please see http://wiki.ros.org/sw_urdf_exporter -->
<robot name="piper_l_camera">
  <material name="aluminum">
    <color rgba="0.5 0.5 0.5 1"/>
  </material>
  <material name="plastic">
    <color rgba="0.1 0.1 0.1 1"/>
  </material>
  <link name="d435_camera_link"/>
  <!-- camera body, with origin at bottom screw mount -->
  <joint name="camera_joint" type="fixed">
    <origin rpy="0 0 0" xyz="0 0 0"/>
    <parent link="d435_camera_link"/>
    <child link="camera_bottom_screw_frame"/>
  </joint>
  <link name="camera_bottom_screw_frame"/>
  <joint name="camera_link_joint" type="fixed">
    <origin rpy="0 0 0" xyz="0.010600000000000002 0.0175 0.0125"/>
    <parent link="camera_bottom_screw_frame"/>
    <child link="camera_link"/>
  </joint>
  <link name="camera_link">
    <visual>
      <!-- the mesh origin is at front plate in between the two infrared camera axes -->
      <origin rpy="1.5707963267948966 0 1.5707963267948966" xyz="0.0043 -0.0175 0"/>
      <geometry>
        <mesh filename="package://realsense2_description/meshes/d435.STL"/>
      </geometry>
    </visual>
    <collision>
      <origin rpy="0 0 0" xyz="0 -0.0175 0"/>
      <geometry>
        <box size="0.02505 0.09 0.025"/>
      </geometry>
    </collision>
    <inertial>
      <!-- The following are not reliable values, and should not be used for modeling -->
      <mass value="0.072"/>
      <origin xyz="0 0 0"/>
      <inertia ixx="0.003881243" ixy="0.0" ixz="0.0" iyy="0.000498940" iyz="0.0" izz="0.003879257"/>
    </inertial>
  </link>
  <!-- <xacro:if value="${add_plug}">
      <xacro:usb_plug parent="${name}_link" name="${name}_usb_plug">
        <origin xyz="${d435_cam_mount_from_center_offset - 0.02095} ${-d435_cam_depth_py - 0.0353} 0" rpy="0 0 0"/>
      </xacro:usb_plug>
    </xacro:if> -->
  <link name="base_link">
    <inertial>
      <origin rpy="0 0 0" xyz="-0.00347 -0.00012 0.04283"/>
      <mass value="1.07"/>
      <inertia ixx="0.00099887" ixy="0.00000194" ixz="0.00000613" iyy="0.00112771" iyz="0.00000201" izz="0.00096552"/>
    </inertial>
    <visual>
      <origin rpy="0 0 0" xyz="0 0 0"/>
      <geometry>
        <mesh filename="package://piper_l_description/meshes/dae/dark_dae/base_link.STL"/>
      </geometry>
      <material name="">
        <color rgba="1 1 1 1"/>
      </material>
    </visual>
    <collision>
      <origin rpy="0 0 0" xyz="0 0 0"/>
      <geometry>
        <mesh filename="package://piper_l_description/meshes/dae/dark_dae/base_link.STL"/>
      </geometry>
    </collision>
  </link>
  <link name="link1">
    <inertial>
      <origin rpy="0 0 0" xyz="0.00201 -0.00220 -0.02127"/>
      <mass value="0.11"/>
      <inertia ixx="0.00011279" ixy="0.00000011" ixz="0.00000186" iyy="0.00007274" iyz="0.00000781" izz="0.00011091"/>
    </inertial>
    <visual>
      <origin rpy="0 0 0" xyz="0 0 0"/>
      <geometry>
        <mesh filename="package://piper_l_description/meshes/dae/dark_dae/link1.STL"/>
      </geometry>
      <material name="">
        <color rgba="1 1 1 1"/>
      </material>
    </visual>
    <collision>
      <origin rpy="0 0 0" xyz="0 0 0"/>
      <geometry>
        <mesh filename="package://piper_l_description/meshes/dae/dark_dae/link1.STL"/>
      </geometry>
    </collision>
  </link>
  <joint name="joint1" type="revolute">
    <origin rpy="0 0 0" xyz="0 0 0.123"/>
    <parent link="base_link"/>
    <child link="link1"/>
    <axis xyz="0 0 1"/>
    <limit effort="100" lower="-2.618" upper="2.618" velocity="3"/>
  </joint>
  <link name="link2">
    <inertial>
      <origin rpy="0 0 0" xyz="0.25986 -0.00913 0.00237"/>
      <mass value="1.16"/>
      <inertia ixx="0.00096865" ixy="0.00041154" ixz="0.00005836" iyy="0.01629404" iyz="0.00001694" izz="0.01628996"/>
    </inertial>
    <visual>
      <origin rpy="0 0.0 0" xyz="0 0 0"/>
      <geometry>
        <mesh filename="package://piper_l_description/meshes/dae/dark_dae/link2.STL"/>
      </geometry>
      <material name="">
        <color rgba="1 1 1 1"/>
      </material>
    </visual>
    <collision>
      <origin rpy="0 0 0" xyz="0 0 0"/>
      <geometry>
        <mesh filename="package://piper_l_description/meshes/dae/dark_dae/link2.STL"/>
      </geometry>
    </collision>
  </link>
  <joint name="joint2" type="revolute">
    <origin rpy="1.5708 -0.1745 3.1416" xyz="0 0 0"/>
    <parent link="link1"/>
    <child link="link2"/>
    <axis xyz="0 0 1"/>
    <limit effort="100" lower="0" upper="3.14" velocity="3"/>
  </joint>
  <link name="link3">
    <inertial>
      <origin rpy="0 0 0" xyz="-0.00726 -0.19029 -0.00045"/>
      <mass value="0.59"/>
      <inertia ixx="0.00558278" ixy="0.00018354" ixz="0.00000254" iyy="0.00026568" iyz="0.00005267" izz="0.00554212"/>
    </inertial>
    <visual>
      <origin rpy="0 0 0" xyz="0 0 0"/>
      <geometry>
        <mesh filename="package://piper_l_description/meshes/dae/dark_dae/link3.STL"/>
      </geometry>
      <material name="">
        <color rgba="1 1 1 1"/>
      </material>
    </visual>
    <collision>
      <origin rpy="0 0 0" xyz="0 0 0"/>
      <geometry>
        <mesh filename="package://piper_l_description/meshes/dae/dark_dae/link3.STL"/>
      </geometry>
    </collision>
  </link>
  <joint name="joint3" type="revolute">
    <origin rpy="0 0 -1.8325" xyz="0.33823 0 0"/>
    <parent link="link2"/>
    <child link="link3"/>
    <axis xyz="0 0 1"/>
    <limit effort="100" lower="-2.697" upper="0" velocity="3"/>
  </joint>
  <link name="link4">
    <inertial>
      <origin rpy="0 0 0" xyz="0.00054 -0.00162 -0.00399"/>
      <mass value="0.37"/>
      <inertia ixx="0.00017066" ixy="0.00000129" ixz="0.00000316" iyy="0.00017128" iyz="0.00000775" izz="0.00014437"/>
    </inertial>
    <visual>
      <origin rpy="0 0 0" xyz="0 0 0"/>
      <geometry>
        <mesh filename="package://piper_l_description/meshes/dae/dark_dae/link4.STL"/>
      </geometry>
      <material name="">
        <color rgba="1 1 1 1"/>
      </material>
    </visual>
    <collision>
      <origin rpy="0 0 0" xyz="0 0 0"/>
      <geometry>
        <mesh filename="package://piper_l_description/meshes/dae/dark_dae/link4.STL"/>
      </geometry>
    </collision>
  </link>
  <joint name="joint4" type="revolute">
    <origin rpy="1.5708 0 0.0" xyz="0 -0.3215 0"/>
    <parent link="link3"/>
    <child link="link4"/>
    <axis xyz="0 0 1"/>
    <limit effort="100" lower="-1.832" upper="1.832" velocity="3"/>
  </joint>
  <link name="link5">
    <inertial>
      <origin rpy="0 0 0" xyz="0.0002 -0.06142 -0.00257"/>
      <mass value="0.38"/>
      <inertia ixx="0.00029534" ixy="0.00000167" ixz="0.00000016" iyy="0.00016988" iyz="0.00005020" izz="0.00028334"/>
    </inertial>
    <visual>
      <origin rpy="0 0 0" xyz="0 0 0"/>
      <geometry>
        <mesh filename="package://piper_l_description/meshes/dae/dark_dae/link5.STL"/>
      </geometry>
      <material name="">
        <color rgba="1 1 1 1"/>
      </material>
    </visual>
    <collision>
      <origin rpy="0 0 0" xyz="0 0 0"/>
      <geometry>
        <mesh filename="package://piper_l_description/meshes/dae/dark_dae/link5.STL"/>
      </geometry>
    </collision>
  </link>
  <joint name="joint5" type="revolute">
    <origin rpy="-1.5708 0.0 0" xyz="0 0 0"/>
    <parent link="link4"/>
    <child link="link5"/>
    <axis xyz="0 0 -1"/>
    <limit effort="100" lower="-1.22" upper="1.22" velocity="3"/>
  </joint>
  <link name="link6">
    <inertial>
      <origin rpy="0 0 0" xyz="-3.49720252756924E-15 -3.47851379593264E-06 -0.00315807577104896"/>
      <mass value="0.00563228459599247"/>
      <inertia ixx="5.13060019382932E-07" ixy="-1.55709158367416E-20" ixz="1.27617424904681E-19" iyy="5.13060019383189E-07" iyz="6.20132760426175E-20" izz="9.81761489300716E-07"/>
    </inertial>
    <visual>
      <origin rpy="-1.57 0 1.57" xyz="0.008 -0.002 0.064"/>
      <geometry>
        <mesh filename="package://piper_l_description/meshes/dae/gripper_base_100_v3.STL" scale="1 1 1"/>
      </geometry>
      <material name="">
        <color rgba="1 1 1 1"/>
      </material>
    </visual>
    <collision>
      <origin rpy="-1.57 0 1.57" xyz="0.008 -0.002 0.064"/>
      <geometry>
        <mesh filename="package://piper_l_description/meshes/dae/gripper_base_100_v3.STL" scale="1 1 1"/>
      </geometry>
    </collision>
  </link>
  <joint name="joint6" type="revolute">
    <origin rpy="1.5708 0 0" xyz="0 -0.091 0"/>
    <parent link="link5"/>
    <child link="link6"/>
    <axis xyz="0 0 1"/>
    <limit effort="100" lower="-3.14" upper="3.14" velocity="3"/>
  </joint>
  <link name="link7">
    <inertial>
      <origin rpy="0 0 0" xyz="0.000277816920932317 -0.0467673824063769 -0.00921030054508036"/>
      <mass value="0.0264822021416248"/>
      <inertia ixx="9.99779119357223E-06" ixy="-1.57542283433504E-07" ixz="2.71367446701359E-08" iyy="6.17952441557932E-06" iyz="1.58939319453383E-06" izz="1.4210192754512E-05"/>
    </inertial>
    <visual>
      <geometry>
        <mesh filename="package://piper_l_description/meshes/dae/link7.STL"/>
      </geometry>
      <material name="LightGrey">
        <color rgba="0.7 0.7 0.7 1.0"/>
      </material>
    </visual>
    <collision>
      <geometry>
        <mesh filename="package://piper_l_description/meshes/dae/link7.STL"/>
      </geometry>
    </collision>
  </link>
  <joint name="joint7" type="prismatic">
    <origin rpy="1.5708 0 0" xyz="0 0 0.13503"/>
    <parent link="link6"/>
    <child link="link7"/>
    <axis xyz="0 0 -1"/>
    <limit effort="100" lower="0" upper="0.05" velocity="1"/>
  </joint>
  <link name="link8">
    <inertial>
      <origin rpy="0 0 0" xyz="0.000277816920932317 0.0467673824063769 -0.00921030054508036"/>
      <mass value="0.0264822021416248"/>
      <inertia ixx="9.99779119357223E-06" ixy="-1.57542283433504E-07" ixz="2.71367446701359E-08" iyy="6.17952441557932E-06" iyz="1.58939319453383E-06" izz="1.4210192754512E-05"/>
    </inertial>
    <visual>
      <origin rpy="0 0 0" xyz="0 0 0"/>
      <geometry>
        <mesh filename="package://piper_l_description/meshes/dae/link8.STL"/>
      </geometry>
      <material name="">
        <color rgba="0.792156862745098 0.819607843137255 0.933333333333333 1"/>
      </material>
    </visual>
    <collision>
      <origin rpy="0 0 0" xyz="0 0 0"/>
      <geometry>
        <mesh filename="package://piper_l_description/meshes/dae/link8.STL"/>
      </geometry>
    </collision>
  </link>
  <joint name="joint8" type="prismatic">
    <origin rpy="-1.5708 0 0" xyz="0 0 0.13503"/>
    <parent link="link6"/>
    <child link="link8"/>
    <axis xyz="0 0 1"/>
    <limit effort="100" lower="-0.05" upper="0" velocity="1"/>
  </joint>
  <link name="camera_stand_link">
    <inertial>
      <origin rpy="0.0 0.0 0.0" xyz="0.0 0.0 0.0"/>
      <mass value="0.0"/>
      <inertia ixx="0.0" ixy="0.0" ixz="0.0" iyy="0.0" iyz="0.0" izz="0.0"/>
    </inertial>
    <visual name="">
      <origin rpy="0.0 3.14 1.57" xyz="0.0 0.0 0.0"/>
      <geometry>
        <mesh filename="package://piper_l_description/meshes/dae/realsense_mid_stand_v2.STL"/>
      </geometry>
    </visual>
    <collision>
      <origin rpy="0.0 3.14 1.57" xyz="0.0 0.0 0.0"/>
      <geometry>
        <mesh filename="package://piper_l_description/meshes/dae/realsense_mid_stand_v2.STL"/>
      </geometry>
    </collision>
  </link>
  <joint name="camera_stand_joint" type="fixed">
    <origin rpy="0 0 0" xyz="-0.034 -0.002 0.023"/>
    <parent link="link6"/>
    <child link="camera_stand_link"/>
    <axis xyz="0.0 0.0 0.0"/>
    <limit effort="0.0" lower="0.0" upper="0.0" velocity="0.0"/>
  </joint>
  <joint name="d435_camera_joint" type="fixed">
    <origin rpy="0.0 -1.22 0" xyz="-0.032 -0.028 0.0"/>
    <parent link="camera_stand_link"/>
    <child link="d435_camera_link"/>
    <axis xyz="0.0 0.0 0.0"/>
    <limit effort="0.0" lower="0.0" upper="0.0" velocity="0.0"/>
  </joint>
</robot>
